<?xml version="1.0" encoding="utf-8"?>
<!-- This URDF was automatically created by SolidWorks to URDF Exporter! Originally created by Stephen Brawner (brawner@gmail.com) 
     Commit Version: 1.6.0-4-g7f85cfe  Build Version: 1.6.7995.38578
     For more information, please see http://wiki.ros.org/sw_urdf_exporter -->
<robot
  name="Modelo2">
  <link
    name="base_link">
    <inertial>
      <origin
        xyz="-6.93889390390723E-18 -5.54594813511036E-05 -0.0069065551588681"
        rpy="0 0 0" />
      <mass
        value="1.59520800913696" />
      <inertia
        ixx="0.0192985567988263"
        ixy="8.58141631513745E-13"
        ixz="-1.49239290594735E-19"
        iyy="0.0191562098974604"
        iyz="-0.000152041178230972"
        izz="0.0382179086633143" />
    </inertial>
    <visual>
      <origin
        xyz="0 0 0"
        rpy="0 0 0" />
      <geometry>
        <mesh
          filename="package://Modelo2/meshes/base_link.STL" />
      </geometry>
      <material
        name="">
        <color
          rgba="0.894117647058823 0.913725490196078 0.929411764705882 1" />
      </material>
    </visual>
    <collision>
      <origin
        xyz="0 0 0"
        rpy="0 0 0" />
      <geometry>
        <mesh
          filename="package://Modelo2/meshes/base_link.STL" />
      </geometry>
    </collision>
  </link>
  <link
    name="left_wheel">
    <inertial>
      <origin
        xyz="-3.14330033453561E-06 -6.56738631856163E-06 0.0291446115167832"
        rpy="0 0 0" />
      <mass
        value="0.958008205459542" />
      <inertia
        ixx="0.00158534602463517"
        ixy="1.36072608890677E-08"
        ixz="1.65486211393412E-07"
        iyy="0.00158536794192628"
        iyz="3.45755037846536E-07"
        izz="0.0027026878956097" />
    </inertial>
    <visual>
      <origin
        xyz="0 0 0"
        rpy="0 0 0" />
      <geometry>
        <mesh
          filename="package://Modelo2/meshes/left_wheel.STL" />
      </geometry>
      <material
        name="">
        <color
          rgba="0.792156862745098 0.819607843137255 0.933333333333333 1" />
      </material>
    </visual>
    <collision>
      <origin
        xyz="0 0 0"
        rpy="0 0 0" />
      <geometry>
        <mesh
          filename="package://Modelo2/meshes/left_wheel.STL" />
      </geometry>
    </collision>
  </link>
  <joint
    name="leftwheel_joint"
    type="continuous">
    <origin
      xyz="0 0.18 0.022"
      rpy="1.5708 0 0" />
    <parent
      link="base_link" />
    <child
      link="left_wheel" />
    <axis
      xyz="0 0 -1" />
    <limit
      effort="6.5"
      velocity="40" />
    <dynamics
      friction="0.1" />
  </joint>
  <link
    name="right_wheel">
    <inertial>
      <origin
        xyz="9.03817139359664E-08 -7.28029456295359E-06 -0.0291446514181855"
        rpy="0 0 0" />
      <mass
        value="0.95800858734738" />
      <inertia
        ixx="0.00158533951727554"
        ixy="-4.33732580100363E-10"
        ixz="4.75834716119502E-09"
        iyy="0.00158537444928592"
        iyz="-3.83287868957562E-07"
        izz="0.0027026878956097" />
    </inertial>
    <visual>
      <origin
        xyz="0 0 0"
        rpy="0 0 0" />
      <geometry>
        <mesh
          filename="package://Modelo2/meshes/right_wheel.STL" />
      </geometry>
      <material
        name="">
        <color
          rgba="0.792156862745098 0.819607843137255 0.933333333333333 1" />
      </material>
    </visual>
    <collision>
      <origin
        xyz="0 0 0"
        rpy="0 0 0" />
      <geometry>
        <mesh
          filename="package://Modelo2/meshes/right_wheel.STL" />
      </geometry>
    </collision>
  </link>
  <joint
    name="rightwheel_joint"
    type="continuous">
    <origin
      xyz="0 -0.18 0.022"
      rpy="1.5708 0 0" />
    <parent
      link="base_link" />
    <child
      link="right_wheel" />
    <axis
      xyz="0 0 1" />
    <limit
      effort="6.5"
      velocity="40" />
    <dynamics
      friction="0.1" />
  </joint>
  <link
    name="front_caster">
    <inertial>
      <origin
        xyz="0.00719645182828996 5.27849148379716E-05 -0.0129869427741275"
        rpy="0 0 0" />
      <mass
        value="0.0345228972247052" />
      <inertia
        ixx="8.7256705327778E-06"
        ixy="1.6376475932051E-09"
        ixz="1.70393496562884E-06"
        iyy="8.4680866315482E-06"
        iyz="1.28132864003398E-08"
        izz="9.95030505700406E-06" />
    </inertial>
    <visual>
      <origin
        xyz="0 0 0"
        rpy="0 0 0" />
      <geometry>
        <mesh
          filename="package://Modelo2/meshes/front_caster.STL" />
      </geometry>
      <material
        name="">
        <color
          rgba="0.780392156862745 0.76078431372549 0.741176470588235 1" />
      </material>
    </visual>
    <collision>
      <origin
        xyz="0 0 0"
        rpy="0 0 0" />
      <geometry>
        <mesh
          filename="package://Modelo2/meshes/front_caster.STL" />
      </geometry>
    </collision>
  </link>
  <joint
    name="frontcaster_joint"
    type="continuous">
    <origin
      xyz="0.18128 -0.0025 -0.003"
      rpy="0 0 0" />
    <parent
      link="base_link" />
    <child
      link="front_caster" />
    <axis
      xyz="0 0 1" />
  </joint>
  <link
    name="front_caster_wheel">
    <inertial>
      <origin
        xyz="0 0 -1.30104260698261E-18"
        rpy="0 0 0" />
      <mass
        value="0.0241433930709178" />
      <inertia
        ixx="3.43879451958221E-06"
        ixy="3.83223843367824E-22"
        ixz="1.46535404494117E-08"
        iyy="3.4386872810978E-06"
        iyz="-4.2502845668815E-21"
        izz="5.44101180937204E-06" />
    </inertial>
    <visual>
      <origin
        xyz="0 0 0"
        rpy="0 0 0" />
      <geometry>
        <mesh
          filename="package://Modelo2/meshes/front_caster_wheel.STL" />
      </geometry>
      <material
        name="">
        <color
          rgba="0.109803921568627 0.109803921568627 0.109803921568627 1" />
      </material>
    </visual>
    <collision>
      <origin
        xyz="0 0 0"
        rpy="0 0 0" />
      <geometry>
        <mesh
          filename="package://Modelo2/meshes/front_caster_wheel.STL" />
      </geometry>
    </collision>
  </link>
  <joint
    name="frontcasterwheel_joint"
    type="continuous">
    <origin
      xyz="0.019933 0.00014587 -0.0335"
      rpy="1.5708 0 0" />
    <parent
      link="front_caster" />
    <child
      link="front_caster_wheel" />
    <axis
      xyz="0.0073181 0 0.99997" />
    <dynamics
      friction="0.1" />
  </joint>
  <link
    name="back_caster">
    <inertial>
      <origin
        xyz="-0.00719637451878952 6.26008290069229E-05 -0.012986943563235"
        rpy="0 0 0" />
      <mass
        value="0.0345228978243338" />
      <inertia
        ixx="8.72565670210285E-06"
        ixy="-2.49113210026492E-09"
        ixz="-1.70392265602734E-06"
        iyy="8.46810352891274E-06"
        iyz="1.45080704401875E-08"
        izz="9.95030487155889E-06" />
    </inertial>
    <visual>
      <origin
        xyz="0 0 0"
        rpy="0 0 0" />
      <geometry>
        <mesh
          filename="package://Modelo2/meshes/back_caster.STL" />
      </geometry>
      <material
        name="">
        <color
          rgba="0.780392156862745 0.76078431372549 0.741176470588235 1" />
      </material>
    </visual>
    <collision>
      <origin
        xyz="0 0 0"
        rpy="0 0 0" />
      <geometry>
        <mesh
          filename="package://Modelo2/meshes/back_caster.STL" />
      </geometry>
    </collision>
  </link>
  <joint
    name="backcaster_joint"
    type="continuous">
    <origin
      xyz="-0.182778643696715 -0.00250000000000012 -0.00300000000000001"
      rpy="0 0 0" />
    <parent
      link="base_link" />
    <child
      link="back_caster" />
    <axis
      xyz="0 0 1" />
  </joint>
  <link
    name="back_caster_wheel">
    <inertial>
      <origin
        xyz="0 -6.93889390390723E-18 4.33680868994202E-19"
        rpy="0 0 0" />
      <mass
        value="0.0241433930709178" />
      <inertia
        ixx="3.43883937316653E-06"
        ixy="-9.76595632316455E-23"
        ixz="-1.74508125282442E-08"
        iyy="3.4386872810978E-06"
        iyz="2.06750280740556E-21"
        izz="5.44096695578772E-06" />
    </inertial>
    <visual>
      <origin
        xyz="0 0 0"
        rpy="0 0 0" />
      <geometry>
        <mesh
          filename="package://Modelo2/meshes/back_caster_wheel.STL" />
      </geometry>
      <material
        name="">
        <color
          rgba="0.109803921568627 0.109803921568627 0.109803921568627 1" />
      </material>
    </visual>
    <collision>
      <origin
        xyz="0 0 0"
        rpy="0 0 0" />
      <geometry>
        <mesh
          filename="package://Modelo2/meshes/back_caster_wheel.STL" />
      </geometry>
    </collision>
  </link>
  <joint
    name="backcasterwheel_joint"
    type="continuous">
    <origin
      xyz="-0.019933 0.00017372 -0.0335"
      rpy="1.5708 0 0" />
    <parent
      link="back_caster" />
    <child
      link="back_caster_wheel" />
    <axis
      xyz="0.0087151 0 -0.99996" />
    <dynamics
      friction="0.1" />
  </joint>
</robot>